<?xml version="1.0" encoding="UTF-8"?>
<!-- Generated by org.testng.reporters.JUnitReportReporter -->
<testsuite hostname="Avinash-Kumar" failures="4" tests="5" name="topic_DataDrivenFW_DataProvider.TestDataDriven_SwagDemo2" time="115.045" errors="0" timestamp="2022-07-08T23:55:07 IST" skipped="0">
  <testcase classname="topic_DataDrivenFW_DataProvider.TestDataDriven_SwagDemo2" name="loginSauceDemo" time="30.451"/>
  <system-out/>
  <testcase classname="topic_DataDrivenFW_DataProvider.TestDataDriven_SwagDemo2" name="loginSauceDemo" time="20.609">
    <failure message="expected [https://www.saucedemo.com/inventory.html] but found [https://www.saucedemo.com/]" type="java.lang.AssertionError">
      <![CDATA[java.lang.AssertionError: expected [https://www.saucedemo.com/inventory.html] but found [https://www.saucedemo.com/]
at org.testng.Assert.fail(Assert.java:110)
at org.testng.Assert.failNotEquals(Assert.java:1413)
at org.testng.Assert.assertEqualsImpl(Assert.java:149)
at org.testng.Assert.assertEquals(Assert.java:131)
at org.testng.Assert.assertEquals(Assert.java:655)
at org.testng.Assert.assertEquals(Assert.java:665)
at topic_DataDrivenFW_DataProvider.TestDataDriven_SwagDemo2.loginSauceDemo(TestDataDriven_SwagDemo2.java:58)
at java.base/jdk.internal.reflect.NativeMethodAccessorImpl.invoke0(Native Method)
at java.base/jdk.internal.reflect.NativeMethodAccessorImpl.invoke(NativeMethodAccessorImpl.java:77)
at java.base/jdk.internal.reflect.DelegatingMethodAccessorImpl.invoke(DelegatingMethodAccessorImpl.java:43)
at java.base/java.lang.reflect.Method.invoke(Method.java:568)
at org.testng.internal.invokers.MethodInvocationHelper.invokeMethod(MethodInvocationHelper.java:139)
at org.testng.internal.invokers.TestInvoker.invokeMethod(TestInvoker.java:677)
at org.testng.internal.invokers.TestInvoker.invokeTestMethod(TestInvoker.java:221)
at org.testng.internal.invokers.MethodRunner.runInSequence(MethodRunner.java:50)
at org.testng.internal.invokers.TestInvoker$MethodInvocationAgent.invoke(TestInvoker.java:962)
at org.testng.internal.invokers.TestInvoker.invokeTestMethods(TestInvoker.java:194)
at org.testng.internal.invokers.TestMethodWorker.invokeTestMethods(TestMethodWorker.java:148)
at org.testng.internal.invokers.TestMethodWorker.run(TestMethodWorker.java:128)
at java.base/java.util.ArrayList.forEach(ArrayList.java:1511)
at org.testng.TestRunner.privateRun(TestRunner.java:806)
at org.testng.TestRunner.run(TestRunner.java:601)
at org.testng.SuiteRunner.runTest(SuiteRunner.java:433)
at org.testng.SuiteRunner.runSequentially(SuiteRunner.java:427)
at org.testng.SuiteRunner.privateRun(SuiteRunner.java:387)
at org.testng.SuiteRunner.run(SuiteRunner.java:330)
at org.testng.SuiteRunnerWorker.runSuite(SuiteRunnerWorker.java:52)
at org.testng.SuiteRunnerWorker.run(SuiteRunnerWorker.java:95)
at org.testng.TestNG.runSuitesSequentially(TestNG.java:1256)
at org.testng.TestNG.runSuitesLocally(TestNG.java:1176)
at org.testng.TestNG.runSuites(TestNG.java:1099)
at org.testng.TestNG.run(TestNG.java:1067)
at org.apache.maven.surefire.testng.TestNGExecutor.run(TestNGExecutor.java:281)
at org.apache.maven.surefire.testng.TestNGXmlTestSuite.execute(TestNGXmlTestSuite.java:75)
at org.apache.maven.surefire.testng.TestNGProvider.invoke(TestNGProvider.java:121)
at org.apache.maven.surefire.booter.ForkedBooter.invokeProviderInSameClassLoader(ForkedBooter.java:290)
at org.apache.maven.surefire.booter.ForkedBooter.runSuitesInProcess(ForkedBooter.java:242)
at org.apache.maven.surefire.booter.ForkedBooter.main(ForkedBooter.java:121)
]]>
    </failure>
  </testcase> <!-- loginSauceDemo -->
  <system-out/>
  <testcase classname="topic_DataDrivenFW_DataProvider.TestDataDriven_SwagDemo2" name="loginSauceDemo" time="22.136">
    <failure message="expected [https://www.saucedemo.com/inventory.html] but found [https://www.saucedemo.com/]" type="java.lang.AssertionError">
      <![CDATA[java.lang.AssertionError: expected [https://www.saucedemo.com/inventory.html] but found [https://www.saucedemo.com/]
at org.testng.Assert.fail(Assert.java:110)
at org.testng.Assert.failNotEquals(Assert.java:1413)
at org.testng.Assert.assertEqualsImpl(Assert.java:149)
at org.testng.Assert.assertEquals(Assert.java:131)
at org.testng.Assert.assertEquals(Assert.java:655)
at org.testng.Assert.assertEquals(Assert.java:665)
at topic_DataDrivenFW_DataProvider.TestDataDriven_SwagDemo2.loginSauceDemo(TestDataDriven_SwagDemo2.java:58)
at java.base/jdk.internal.reflect.NativeMethodAccessorImpl.invoke0(Native Method)
at java.base/jdk.internal.reflect.NativeMethodAccessorImpl.invoke(NativeMethodAccessorImpl.java:77)
at java.base/jdk.internal.reflect.DelegatingMethodAccessorImpl.invoke(DelegatingMethodAccessorImpl.java:43)
at java.base/java.lang.reflect.Method.invoke(Method.java:568)
at org.testng.internal.invokers.MethodInvocationHelper.invokeMethod(MethodInvocationHelper.java:139)
at org.testng.internal.invokers.TestInvoker.invokeMethod(TestInvoker.java:677)
at org.testng.internal.invokers.TestInvoker.invokeTestMethod(TestInvoker.java:221)
at org.testng.internal.invokers.MethodRunner.runInSequence(MethodRunner.java:50)
at org.testng.internal.invokers.TestInvoker$MethodInvocationAgent.invoke(TestInvoker.java:962)
at org.testng.internal.invokers.TestInvoker.invokeTestMethods(TestInvoker.java:194)
at org.testng.internal.invokers.TestMethodWorker.invokeTestMethods(TestMethodWorker.java:148)
at org.testng.internal.invokers.TestMethodWorker.run(TestMethodWorker.java:128)
at java.base/java.util.ArrayList.forEach(ArrayList.java:1511)
at org.testng.TestRunner.privateRun(TestRunner.java:806)
at org.testng.TestRunner.run(TestRunner.java:601)
at org.testng.SuiteRunner.runTest(SuiteRunner.java:433)
at org.testng.SuiteRunner.runSequentially(SuiteRunner.java:427)
at org.testng.SuiteRunner.privateRun(SuiteRunner.java:387)
at org.testng.SuiteRunner.run(SuiteRunner.java:330)
at org.testng.SuiteRunnerWorker.runSuite(SuiteRunnerWorker.java:52)
at org.testng.SuiteRunnerWorker.run(SuiteRunnerWorker.java:95)
at org.testng.TestNG.runSuitesSequentially(TestNG.java:1256)
at org.testng.TestNG.runSuitesLocally(TestNG.java:1176)
at org.testng.TestNG.runSuites(TestNG.java:1099)
at org.testng.TestNG.run(TestNG.java:1067)
at org.apache.maven.surefire.testng.TestNGExecutor.run(TestNGExecutor.java:281)
at org.apache.maven.surefire.testng.TestNGXmlTestSuite.execute(TestNGXmlTestSuite.java:75)
at org.apache.maven.surefire.testng.TestNGProvider.invoke(TestNGProvider.java:121)
at org.apache.maven.surefire.booter.ForkedBooter.invokeProviderInSameClassLoader(ForkedBooter.java:290)
at org.apache.maven.surefire.booter.ForkedBooter.runSuitesInProcess(ForkedBooter.java:242)
at org.apache.maven.surefire.booter.ForkedBooter.main(ForkedBooter.java:121)
]]>
    </failure>
  </testcase> <!-- loginSauceDemo -->
  <system-out/>
  <testcase classname="topic_DataDrivenFW_DataProvider.TestDataDriven_SwagDemo2" name="loginSauceDemo" time="21.566">
    <failure message="expected [https://www.saucedemo.com/inventory.html] but found [https://www.saucedemo.com/]" type="java.lang.AssertionError">
      <![CDATA[java.lang.AssertionError: expected [https://www.saucedemo.com/inventory.html] but found [https://www.saucedemo.com/]
at org.testng.Assert.fail(Assert.java:110)
at org.testng.Assert.failNotEquals(Assert.java:1413)
at org.testng.Assert.assertEqualsImpl(Assert.java:149)
at org.testng.Assert.assertEquals(Assert.java:131)
at org.testng.Assert.assertEquals(Assert.java:655)
at org.testng.Assert.assertEquals(Assert.java:665)
at topic_DataDrivenFW_DataProvider.TestDataDriven_SwagDemo2.loginSauceDemo(TestDataDriven_SwagDemo2.java:58)
at java.base/jdk.internal.reflect.NativeMethodAccessorImpl.invoke0(Native Method)
at java.base/jdk.internal.reflect.NativeMethodAccessorImpl.invoke(NativeMethodAccessorImpl.java:77)
at java.base/jdk.internal.reflect.DelegatingMethodAccessorImpl.invoke(DelegatingMethodAccessorImpl.java:43)
at java.base/java.lang.reflect.Method.invoke(Method.java:568)
at org.testng.internal.invokers.MethodInvocationHelper.invokeMethod(MethodInvocationHelper.java:139)
at org.testng.internal.invokers.TestInvoker.invokeMethod(TestInvoker.java:677)
at org.testng.internal.invokers.TestInvoker.invokeTestMethod(TestInvoker.java:221)
at org.testng.internal.invokers.MethodRunner.runInSequence(MethodRunner.java:50)
at org.testng.internal.invokers.TestInvoker$MethodInvocationAgent.invoke(TestInvoker.java:962)
at org.testng.internal.invokers.TestInvoker.invokeTestMethods(TestInvoker.java:194)
at org.testng.internal.invokers.TestMethodWorker.invokeTestMethods(TestMethodWorker.java:148)
at org.testng.internal.invokers.TestMethodWorker.run(TestMethodWorker.java:128)
at java.base/java.util.ArrayList.forEach(ArrayList.java:1511)
at org.testng.TestRunner.privateRun(TestRunner.java:806)
at org.testng.TestRunner.run(TestRunner.java:601)
at org.testng.SuiteRunner.runTest(SuiteRunner.java:433)
at org.testng.SuiteRunner.runSequentially(SuiteRunner.java:427)
at org.testng.SuiteRunner.privateRun(SuiteRunner.java:387)
at org.testng.SuiteRunner.run(SuiteRunner.java:330)
at org.testng.SuiteRunnerWorker.runSuite(SuiteRunnerWorker.java:52)
at org.testng.SuiteRunnerWorker.run(SuiteRunnerWorker.java:95)
at org.testng.TestNG.runSuitesSequentially(TestNG.java:1256)
at org.testng.TestNG.runSuitesLocally(TestNG.java:1176)
at org.testng.TestNG.runSuites(TestNG.java:1099)
at org.testng.TestNG.run(TestNG.java:1067)
at org.apache.maven.surefire.testng.TestNGExecutor.run(TestNGExecutor.java:281)
at org.apache.maven.surefire.testng.TestNGXmlTestSuite.execute(TestNGXmlTestSuite.java:75)
at org.apache.maven.surefire.testng.TestNGProvider.invoke(TestNGProvider.java:121)
at org.apache.maven.surefire.booter.ForkedBooter.invokeProviderInSameClassLoader(ForkedBooter.java:290)
at org.apache.maven.surefire.booter.ForkedBooter.runSuitesInProcess(ForkedBooter.java:242)
at org.apache.maven.surefire.booter.ForkedBooter.main(ForkedBooter.java:121)
]]>
    </failure>
  </testcase> <!-- loginSauceDemo -->
  <system-out/>
  <testcase classname="topic_DataDrivenFW_DataProvider.TestDataDriven_SwagDemo2" name="loginSauceDemo" time="20.283">
    <failure message="expected [https://www.saucedemo.com/inventory.html] but found [https://www.saucedemo.com/]" type="java.lang.AssertionError">
      <![CDATA[java.lang.AssertionError: expected [https://www.saucedemo.com/inventory.html] but found [https://www.saucedemo.com/]
at org.testng.Assert.fail(Assert.java:110)
at org.testng.Assert.failNotEquals(Assert.java:1413)
at org.testng.Assert.assertEqualsImpl(Assert.java:149)
at org.testng.Assert.assertEquals(Assert.java:131)
at org.testng.Assert.assertEquals(Assert.java:655)
at org.testng.Assert.assertEquals(Assert.java:665)
at topic_DataDrivenFW_DataProvider.TestDataDriven_SwagDemo2.loginSauceDemo(TestDataDriven_SwagDemo2.java:58)
at java.base/jdk.internal.reflect.NativeMethodAccessorImpl.invoke0(Native Method)
at java.base/jdk.internal.reflect.NativeMethodAccessorImpl.invoke(NativeMethodAccessorImpl.java:77)
at java.base/jdk.internal.reflect.DelegatingMethodAccessorImpl.invoke(DelegatingMethodAccessorImpl.java:43)
at java.base/java.lang.reflect.Method.invoke(Method.java:568)
at org.testng.internal.invokers.MethodInvocationHelper.invokeMethod(MethodInvocationHelper.java:139)
at org.testng.internal.invokers.TestInvoker.invokeMethod(TestInvoker.java:677)
at org.testng.internal.invokers.TestInvoker.invokeTestMethod(TestInvoker.java:221)
at org.testng.internal.invokers.MethodRunner.runInSequence(MethodRunner.java:50)
at org.testng.internal.invokers.TestInvoker$MethodInvocationAgent.invoke(TestInvoker.java:962)
at org.testng.internal.invokers.TestInvoker.invokeTestMethods(TestInvoker.java:194)
at org.testng.internal.invokers.TestMethodWorker.invokeTestMethods(TestMethodWorker.java:148)
at org.testng.internal.invokers.TestMethodWorker.run(TestMethodWorker.java:128)
at java.base/java.util.ArrayList.forEach(ArrayList.java:1511)
at org.testng.TestRunner.privateRun(TestRunner.java:806)
at org.testng.TestRunner.run(TestRunner.java:601)
at org.testng.SuiteRunner.runTest(SuiteRunner.java:433)
at org.testng.SuiteRunner.runSequentially(SuiteRunner.java:427)
at org.testng.SuiteRunner.privateRun(SuiteRunner.java:387)
at org.testng.SuiteRunner.run(SuiteRunner.java:330)
at org.testng.SuiteRunnerWorker.runSuite(SuiteRunnerWorker.java:52)
at org.testng.SuiteRunnerWorker.run(SuiteRunnerWorker.java:95)
at org.testng.TestNG.runSuitesSequentially(TestNG.java:1256)
at org.testng.TestNG.runSuitesLocally(TestNG.java:1176)
at org.testng.TestNG.runSuites(TestNG.java:1099)
at org.testng.TestNG.run(TestNG.java:1067)
at org.apache.maven.surefire.testng.TestNGExecutor.run(TestNGExecutor.java:281)
at org.apache.maven.surefire.testng.TestNGXmlTestSuite.execute(TestNGXmlTestSuite.java:75)
at org.apache.maven.surefire.testng.TestNGProvider.invoke(TestNGProvider.java:121)
at org.apache.maven.surefire.booter.ForkedBooter.invokeProviderInSameClassLoader(ForkedBooter.java:290)
at org.apache.maven.surefire.booter.ForkedBooter.runSuitesInProcess(ForkedBooter.java:242)
at org.apache.maven.surefire.booter.ForkedBooter.main(ForkedBooter.java:121)
]]>
    </failure>
  </testcase> <!-- loginSauceDemo -->
  <system-out/>
</testsuite> <!-- topic_DataDrivenFW_DataProvider.TestDataDriven_SwagDemo2 -->
